Workbook
Name 使用銃: データシート!$A$35:$A$37
Name 場所: データシート!$A$12:$A$31
Name 用途: データシート!$A$2:$A$7

Sheet 表紙
A5: 実 包 等 管 理 帳 簿
B15: 自 | D15: 2019 | E15: 年 | F15: 10 | G15: 月 | H15: 26 | I15: 日
B16: 至 | D16: 2021 | E16: 年 | F16: 4 | G16: 月 | H16: 19 | I16: 日
B17: 住所 （実包保管場所） | G17: 愛知県田原市浦町尾﨑１３番地
B18: 氏名 | G18: 鈴木 翔一郎
B19: 電話番号（自宅） | G19: 0531-22-3064
B20: 携帯番号 | G20: 090-8676-1049
B28: ≪帳簿記載は銃砲刀剣類所持等取締法第10の5で義務付けされています。
G30: 受払の都度記帳して下さい。≫

Sheet 帳簿
B1: 実包等管理帳簿（射撃、狩猟、有害） | P1: 作成 | Q1: =MIN(B12:B51) -> 45957
P2: 最終更新 | Q2: =MAX(B12:B51) -> 46387
B3: 実包種類･名称：散弾12番径 | P3: 保存期間 | Q3: =DATE(YEAR(Q2)+3,MONTH(Q2),DAY(Q2)) -> 47483
D4: 射撃 | I4: 狩猟/有害
C5: 弾種→ | D5: =D11 -> Slug | E5: =E11 -> 他 | F5: =F11 -> 7.5号 | G5: =G11 -> 9号 | H5: =H11 -> (予備) | I5: =I11 -> Slug | J5: =J11 -> 他 | K5: =K11 -> 9粒 | ... N5: =N11 -> 3号
C6: 繰越 | D6: 0 | E6: 85 | F6: 12 | G6: 73 | H6: 0 | I6: 26 | J6: 32 | K6: 12 | L6: 2 | M6: 0 | N6: 18
C7: 購入合計 | D7: =SUMIF(D12:D51,">0",D12:D51) -> 0 | E7: =SUMIF(E11:E50,">0",E11:E50) -> 200 | F7: =SUMIF(F11:F50,">0",F11:F50) -> 0 | G7: =SUMIF(G11:G50,">0",G11:G50) -> 200 | H7: =SUMIF(H11:H50,">0",H11:H50) -> 0 | I7: =SUMIF(I11:I50,">0",I11:I50) -> 10 | J7: =SUMIF(J11:J50,">0",J11:J50) -> 50 | K7: =SUMIF(K11:K50,">0",K11:K50) -> 0 | L7: =SUMIF(L11:L50,">0",L11:L50) -> 0 | ... N7: =SUMIF(N11:N50,">0",N11:N50) -> 0
C8: 消費合計 | D8: =SUMIF(D12:D51,"<0",D12:D51) -> 0 | E8: =SUMIF(E12:E51,"<0",E12:E51) -> 0 | F8: =SUMIF(F12:F51,"<0",F12:F51) -> 0 | G8: =SUMIF(G12:G51,"<0",G12:G51) -> 0 | H8: =SUMIF(H12:H51,"<0",H12:H51) -> 0 | I8: =SUMIF(I12:I51,"<0",I12:I51) -> -11 | J8: =SUMIF(J12:J51,"<0",J12:J51) -> -15 | K8: =SUMIF(K12:K51,"<0",K12:K51) -> 0 | ... N8: =SUMIF(N12:N51,"<0",N12:N51) -> -3
C9: 残弾 | D9: =D6+SUM(D12:D51) -> 0 | E9: =SUM(F9:H9) -> 285 | F9: =F6+SUM(F12:F51) -> 12 | G9: =G6+SUM(G12:G51) -> 273 | H9: =H6+SUM(H12:H51) -> 0 | I9: =I6+SUM(I12:I51) -> 25 | J9: =SUM(K9:N9) -> 67 | K9: =K6+SUM(K12:K51) -> 12 | L9: =L6+SUM(L12:L51) -> 1 | M9: =M6+SUM(M12:M51) -> 39 | N9: =N6+SUM(N12:N51) -> 15
D10: ="合計："&SUM(D9:E9) -> 合計：285 | I10: ="合計："&SUM(I9:J9) -> 合計：92
B11: 日付 | C11: 用途 | D11: Slug | E11: 他 | F11: 7.5号 | G11: 9号 | H11: (予備) | I11: Slug | J11: 他 | K11: 9粒 | L11: 5号 | M11: 7.5号 | N11: 3号 | O11: 場所 | P11: 使用銃 | Q11: 猟果(目撃)
B12: 45957 | C12: 射撃 | E12: =IF(SUM(F12:H12)=0,"",SUM(F12:H12)) | I12: -8 | J12: =IF(SUM(K12:N12)=0,"",SUM(K12:N12)) | O12: 富士国際岩本山総合射撃場 | P12: M500
B13: 45960 | C13: 購入 | E13: =IF(SUM(F13:H13)=0,"",SUM(F13:H13)) -> 200 | G13: 200 | I13: 10 | J13: =IF(SUM(K13:N13)=0,"",SUM(K13:N13)) -> 50 | M13: 50 | O13: =IFERROR(VLOOKUP(#REF!,表紙記号!$B$15:$C$26,2,FALSE),"")
B14: 45976 | C14: 狩猟 | E14: =IF(SUM(F14:H14)=0,"",SUM(F14:H14)) | J14: =IF(SUM(K14:N14)=0,"",SUM(K14:N14)) -> -15 | L14: -1 | M14: -11 | N14: -3 | O14: 田原市一円 | P14: M500 | Q14: カルガモ3
B15: 45977 | C15: 狩猟 | E15: =IF(SUM(F15:H15)=0,"",SUM(F15:H15)) | J15: =IF(SUM(K15:N15)=0,"",SUM(K15:N15)) | O15: 田原市宇津江 | P15: M500
B16: 45983 | C16: 狩猟 | E16: =IF(SUM(F16:H16)=0,"",SUM(F16:H16)) | J16: =IF(SUM(K16:N16)=0,"",SUM(K16:N16)) | O16: 田原市宇津江 | P16: M500
B17: 45984 | C17: 狩猟 | E17: =IF(SUM(F17:H17)=0,"",SUM(F17:H17)) | J17: =IF(SUM(K17:N17)=0,"",SUM(K17:N17)) | O17: 田原市野田 | P17: M500
B18: 45991 | C18: 狩猟 | E18: =IF(SUM(F18:H18)=0,"",SUM(F18:H18)) | J18: =IF(SUM(K18:N18)=0,"",SUM(K18:N18)) | O18: 田原市宇津江 | P18: M500
B19: 45998 | C19: 狩猟 | E19: =IF(SUM(F19:H19)=0,"",SUM(F19:H19)) | J19: =IF(SUM(K19:N19)=0,"",SUM(K19:N19)) | O19: 田原市宇津江 | P19: M500
B20: 46017 | C20: 狩猟 | E20: =IF(SUM(F20:H20)=0,"",SUM(F20:H20)) | J20: =IF(SUM(K20:N20)=0,"",SUM(K20:N20)) | O20: 田原市宇津江 | P20: M500
B21: 46018 | C21: 狩猟 | E21: =IF(SUM(F21:H21)=0,"",SUM(F21:H21)) | I21: -1 | J21: =IF(SUM(K21:N21)=0,"",SUM(K21:N21)) | O21: 田原市宇津江 | P21: M500
B22: 46019 | C22: 狩猟 | E22: =IF(SUM(F22:H22)=0,"",SUM(F22:H22)) | J22: =IF(SUM(K22:N22)=0,"",SUM(K22:N22)) | O22: 田原市宇津江 | P22: M500
B23: 46385 | C23: 狩猟 | E23: =IF(SUM(F23:H23)=0,"",SUM(F23:H23)) | J23: =IF(SUM(K23:N23)=0,"",SUM(K23:N23)) | O23: 田原市宇津江 | P23: M500
B24: 46387 | C24: 狩猟 | E24: =IF(SUM(F24:H24)=0,"",SUM(F24:H24)) | J24: =IF(SUM(K24:N24)=0,"",SUM(K24:N24)) | O24: 田原市宇津江 | P24: M500
B25: 46024 | C25: 狩猟 | E25: =IF(SUM(F25:H25)=0,"",SUM(F25:H25)) | I25: -2 | J25: =IF(SUM(K25:N25)=0,"",SUM(K25:N25)) | O25: 田原市宇津江 | P25: M500
B26: 46026 | C26: 狩猟 | E26: =IF(SUM(F26:H26)=0,"",SUM(F26:H26)) | J26: =IF(SUM(K26:N26)=0,"",SUM(K26:N26)) | O26: 田原市宇津江 | P26: M500
B27: 46040 | C27: 狩猟 | E27: =IF(SUM(F27:H27)=0,"",SUM(F27:H27)) | J27: =IF(SUM(K27:N27)=0,"",SUM(K27:N27)) | O27: 田原市宇津江 | P27: M500
E28: =IF(SUM(F28:H28)=0,"",SUM(F28:H28)) | J28: =IF(SUM(K28:N28)=0,"",SUM(K28:N28)) | O28: =IFERROR(VLOOKUP(#REF!,表紙記号!$B$15:$C$26,2,FALSE),"")
E29: =IF(SUM(F29:H29)=0,"",SUM(F29:H29)) | J29: =IF(SUM(K29:N29)=0,"",SUM(K29:N29)) | O29: =IFERROR(VLOOKUP(#REF!,表紙記号!$B$15:$C$26,2,FALSE),"")
E30: =IF(SUM(F30:H30)=0,"",SUM(F30:H30)) | J30: =IF(SUM(K30:N30)=0,"",SUM(K30:N30)) | O30: =IFERROR(VLOOKUP(#REF!,表紙記号!$B$15:$C$26,2,FALSE),"")
E31: =IF(SUM(F31:H31)=0,"",SUM(F31:H31)) | J31: =IF(SUM(K31:N31)=0,"",SUM(K31:N31)) | O31: =IFERROR(VLOOKUP(#REF!,表紙記号!$B$15:$C$26,2,FALSE),"")
E32: =IF(SUM(F32:H32)=0,"",SUM(F32:H32)) | J32: =IF(SUM(K32:N32)=0,"",SUM(K32:N32)) | O32: =IFERROR(VLOOKUP(#REF!,表紙記号!$B$15:$C$26,2,FALSE),"")
E33: =IF(SUM(F33:H33)=0,"",SUM(F33:H33)) | J33: =IF(SUM(K33:N33)=0,"",SUM(K33:N33)) | O33: =IFERROR(VLOOKUP(#REF!,表紙記号!$B$15:$C$26,2,FALSE),"")
E34: =IF(SUM(F34:H34)=0,"",SUM(F34:H34)) | J34: =IF(SUM(K34:N34)=0,"",SUM(K34:N34)) | O34: =IFERROR(VLOOKUP(#REF!,表紙記号!$B$15:$C$26,2,FALSE),"")
E35: =IF(SUM(F35:H35)=0,"",SUM(F35:H35)) | J35: =IF(SUM(K35:N35)=0,"",SUM(K35:N35)) | O35: =IFERROR(VLOOKUP(#REF!,表紙記号!$B$15:$C$26,2,FALSE),"")
E36: =IF(SUM(F36:H36)=0,"",SUM(F36:H36)) | J36: =IF(SUM(K36:N36)=0,"",SUM(K36:N36)) | O36: =IFERROR(VLOOKUP(#REF!,表紙記号!$B$15:$C$26,2,FALSE),"")
E37: =IF(SUM(F37:H37)=0,"",SUM(F37:H37)) | J37: =IF(SUM(K37:N37)=0,"",SUM(K37:N37)) | O37: =IFERROR(VLOOKUP(#REF!,表紙記号!$B$15:$C$26,2,FALSE),"")
E38: =IF(SUM(F38:H38)=0,"",SUM(F38:H38)) | J38: =IF(SUM(K38:N38)=0,"",SUM(K38:N38)) | O38: =IFERROR(VLOOKUP(#REF!,表紙記号!$B$15:$C$26,2,FALSE),"")
E39: =IF(SUM(F39:H39)=0,"",SUM(F39:H39)) | J39: =IF(SUM(K39:N39)=0,"",SUM(K39:N39)) | O39: =IFERROR(VLOOKUP(#REF!,表紙記号!$B$15:$C$26,2,FALSE),"")
... E51: =IF(SUM(F51:H51)=0,"",SUM(F51:H51)) | J51: =IF(SUM(K51:N51)=0,"",SUM(K51:N51)) | O51: =IFERROR(VLOOKUP(#REF!,表紙記号!$B$15:$C$26,2,FALSE),"")
...

Sheet 帳簿(認定)
B1: 実包等管理帳簿（認定） | G1: 作成 | H1: =MIN(B12:B41) -> 0
G2: 最終更新 | H2: =MAX(B12:B41) -> 0
B3: 実包種類･名称：散弾12番径 | G3: 保存期間 | H3: =DATE(YEAR(H2)+3,MONTH(H2),DAY(H2)) -> 1096
D4: 認定
C5: 弾種→ | D5: Slug | E5: 他
C6: 繰越 | D6: 0 | E6: 0
C7: 購入合計 | D7: =SUMIF(D12:D41,">0",D12:D41) -> 0 | E7: =SUMIF(E12:E41,">0",E12:E41) -> 0
C8: 消費合計 | D8: =SUMIF(D12:D51,"<0",D12:D51) -> 0 | E8: =SUMIF(E12:E51,"<0",E12:E51) -> 0
C9: 残弾 | D9: =D6+SUM(D12:D41) -> 0 | E9: =E6+SUM(E12:E41) -> 0
D10: ="合計："&SUM(D9:E9) -> 合計：0
B11: 日付 | C11: 用途 | D11: Slug | E11: 他 | F11: 場所 | G11: 使用銃 | H11: 猟果(目撃)
D43: 使用銃
B44: 銃別使用回数 | D44: M500 | E44: -
B45: 認定 | D45: =COUNTIFS($C$12:$C$41,$B45,$G$12:$G$41,D$44) -> 0 | E45: =COUNTIFS($C$12:$C$41,$B45,$G$12:$G$41,E$44) -> 0
B46: 射撃 | D46: =COUNTIFS($C$12:$C$41,$B46,$G$12:$G$41,D$44) -> 0 | E46: =COUNTIFS($C$12:$C$41,$B46,$G$12:$G$41,E$44) -> 0
D47: =COUNTIFS($C$12:$C$41,$B47,$G$12:$G$41,D$44) -> 0 | E47: =COUNTIFS($C$12:$C$41,$B47,$G$12:$G$41,E$44) -> 0

Sheet 更新期限
A1: =TODAY() -> 46047
A2: 内容 | B2: 取得日 | C2: 注意 | D2: アラート | E2: 期限日 | F2: 期限規則
A3: 猟銃用火薬類等譲受許可書 | B3: 44512 | C3: =IF($A$1>D3,"注意","") -> 注意 | D3: =DATE(YEAR(E3),MONTH(E3)-2,DAY(E3)-1) -> 44814 | E3: =DATE(YEAR(B3)+1,MONTH(B3),DAY(B3)-1) -> 44876 | F3: 1年間
A4: 猟銃講習会修了証明書 | B4: 43559 | C4: =IF($A$1>D4,"注意","") -> 注意 | D4: =DATE(YEAR(E4),MONTH(E4)-2,DAY(E4)-1) -> 44594 | E4: =DATE(YEAR(B4)+3,MONTH(B4),DAY(B4)-1) -> 44654 | F4: 3年間
A5: 射撃教習修了証明書 | B5: 43668 | C5: =IF($A$1>D5,"注意","") -> 注意 | D5: =DATE(YEAR(E5),MONTH(E5)-2,DAY(E5)-1) -> 44701 | E5: =DATE(YEAR(B5)+3,MONTH(B5),DAY(B5)-1) -> 44763 | F5: 3年間
A6: 猟銃所持許可証 | B6: 43759 | C6: =IF($A$1>D6,"注意","") -> 注意 | D6: =DATE(YEAR(E6),MONTH(E6)-4,DAY(E6)-1) -> 44491 | E6: =DATE(YEAR(B6)+3,2,23) -> 44615 | F6: 3回目の誕生日まで
A7: 狩猟免状 | B7: 43709 | C7: =IF($A$1>D7,"注意","") -> 注意 | D7: =DATE(YEAR(E7),MONTH(E7)-2,DAY(E7)-1) -> 44742 | E7: =DATE(YEAR(B7)+3,MONTH(B7),DAY(B7)-1) -> 44804 | F7: 3年間

Sheet 帳簿(空気銃)
B1: 空気銃使用実績 | E1: 作成 | F1: =MIN(B6:B34) -> 0
E2: 最終更新 | F2: =MAX(B6:B34) -> 0
E3: 保存期間 | F3: =DATE(YEAR(F2)+3,MONTH(F2),DAY(F2)) -> 1096
B5: 日付 | C5: 用途 | D5: 場所 | E5: 使用銃 | F5: 猟果(目撃)
D9: =IFERROR(VLOOKUP(#REF!,表紙記号!$B$15:$C$26,2,FALSE),"")
D10: =IFERROR(VLOOKUP(#REF!,表紙記号!$B$15:$C$26,2,FALSE),"")
D11: =IFERROR(VLOOKUP(#REF!,表紙記号!$B$15:$C$26,2,FALSE),"")
D12: =IFERROR(VLOOKUP(#REF!,表紙記号!$B$15:$C$26,2,FALSE),"")
D13: =IFERROR(VLOOKUP(#REF!,表紙記号!$B$15:$C$26,2,FALSE),"")
D14: =IFERROR(VLOOKUP(#REF!,表紙記号!$B$15:$C$26,2,FALSE),"")
D15: =IFERROR(VLOOKUP(#REF!,表紙記号!$B$15:$C$26,2,FALSE),"")
D16: =IFERROR(VLOOKUP(#REF!,表紙記号!$B$15:$C$26,2,FALSE),"")
D17: =IFERROR(VLOOKUP(#REF!,表紙記号!$B$15:$C$26,2,FALSE),"")
D18: =IFERROR(VLOOKUP(#REF!,表紙記号!$B$15:$C$26,2,FALSE),"")
D19: =IFERROR(VLOOKUP(#REF!,表紙記号!$B$15:$C$26,2,FALSE),"")
D20: =IFERROR(VLOOKUP(#REF!,表紙記号!$B$15:$C$26,2,FALSE),"")
... D34: =IFERROR(VLOOKUP(#REF!,表紙記号!$B$15:$C$26,2,FALSE),"")
B37: 銃別使用回数 | D37: バイパー
B38: 狩猟 | D38: =COUNTIFS($C$6:$C$34,$B38,$E$6:$E$34,D$37) -> 0
B39: 有害 | D39: =COUNTIFS($C$6:$C$34,$B39,$E$6:$E$34,D$37) -> 0
D40: =COUNTIFS($C$6:$C$34,$B40,$E$6:$E$34,D$37) -> 0

Sheet データシート
A1: 用途
A2: 狩猟
A3: 有害
A4: 射撃
A5: 有害
A6: 購入
A7: 払入
A11: 場所
A12: 田原市福江・保美(Ｂ7027)
A13: 田原市和地(Ｂ7122)
A14: 田原市八王子(Ｂ7172)
A15: 田原市野田地区(Ｂ7177)
... A36: バイパー

Sheet 表紙記号
B3: [名称及び住所、銃所持関連番号記載一覧表]
C4: １. 実包等譲受け先及び主な消費場所 （射撃場等）
B6: 記号 | C6: 銃 番 号 | D6: 名称 | E6: 型式 | F6: 口径 | G6: 用途
B7: ① | C7: V1333253 | D7: モスバーグ500コンボ | E7: スライド式散弾銃 | F7: 12番 | G7: 標的・狩猟・有害
B8: ② | C8: H0004 | D8: CTCバイパー | E8: プリチャージ式空気銃 | F8: 5.5mm | G8: 狩猟・有害
B13: 実包等譲受け先
B14: 記号 | C14: 販売店名 | D14: 住 所
B15: 壱 | C15: 東海火薬銃砲店 | D15: 豊橋市南牛川1-23-13
B16: 弐 | C16: 中京銃砲火薬店 | D16: 名古屋市中区千代田3丁目5-4
B17: 参
B18: 四
B19: 五
B21: 実包等消費場所
B22: 記号 | C22: 射撃場名 | E22: 住 所
B23: A | C23: 愛知県総合射撃場 | E23: 愛知県豊田市宇連野町ウネ畑12-95
B24: B | C24: 静岡クレー射撃場 | E24: 静岡県静岡市駿河区谷田1184
B25: C

Sheet 知人名簿
A1: 木野さん | B1: 田原の方。射撃場で会った
A2: 宮田としのりさん | B2: 福江 | C2: 会長の親戚
A3: 萩原さん | B3: 静岡 清水の猟師
A4: 大久保さん | B4: 田原の猟師 | C4: 初ガルの時に会った
A5: 小久保さん | B5: 初猟の日の午後から一緒にやった
A6: 飯田さん | B6: イノシシ猟に行った
A7: 田中さん | B7: 浜松の人。二回目のイノシシ猟で合った
A8: 堤さん | B8: 2019年から猟をやめた
A9: 小林さん | B9: 認定事業で勢子をやってた
A10: 福井さん | B10: 小久保さんの狩りグループ
A11: 磯部さん（もーがん） | B11: 岡崎のシカ狩りメンバー（田原の認定事業で来ていた）
A12: 柴田さん | B12: 岡崎のシカ狩りメンバー（田原の認定事業で来ていた）。瑞穂メンバー
A13: 北村さん | B13: 瑞穂のメンバー
A14: 吉村さん | B14: 瑞穂メンバー。2021年に銃とった
A15: タケイさん | B15: 2021年認定事業で勢子をやってた。２頭目のイノシシとった時の勢子さん。
A16: リュウジさん | B16: 2023/1/22 津具の巻き狩りの午後ラウンドでマチに案内してもらった

Sheet 身上関係 (裏)
B1: 別添2-１-2
C2: ⑦ | E2: あなたは飲酒しますか
C3: ■ | E3: します | U3: □ | W3: しません
C4: ⑧ | E4: ⑦ で「します」と答えた方へ、 飲酒の頻度を教えてください
C5: □ | E5: ほぼ毎日 | P5: ■ | R5: 時々 | AA5: □ | AC5: 会合程度
C6: ⑨ | E6: ⑦ で 「 します」と答えた方へ、 飲酒したことで失敗したことはありますか
C7: ■ | E7: ない | L7: □ | N7: ある | U7: □ | W7: その他
C8: □ | E8: 保護された | O8: □ | Q8: 他人と喧嘩になった | AA8: □ | AC8: 道路で寝てしまった
C9: ⑩ | E9: ⑦ で 「 します（飲食する）」と答えた方へ、 酒量を教えてください
F10: 晩酌 ：ワイン 200ｍｌ または 日本酒１合 位
C11: ⑪ | E11: あなたはストーカー行為をしたことにより、 警察から注意や警告を受けたことがありますか
C12: ■ | E12: ない | O12: □ | Q12: ある | AA12: □ | AC12: 内容
C13: ⑫ | E13: あなたは悩み事がありますか
C14: ■ | E14: ない
C15: □ | E15: 家族のことで悩みがある
C16: □ | E16: 仕事のことで悩みがある
C17: □ | E17: 近所や友人とのことで悩みがある
C18: □ | E18: その他 | M18: 内容
C19: ⑬ | E19: 破産手続き開始の決定を受けて復権を得ない者に該当しますか
C20: ■ | E20: しない | T20: □ | V20: する
C21: ⑭ | E21: あなたはＤＶ行為者として裁判所から保護命令を受けたことがありますか
C22: ■ | E22: ない | O22: □ | Q22: ある | Z22: いつごろ
C23: ⑮ | E23: あなたはこれまでに自殺を考えたことがありますか
C24: ■ | E24: いいえ | U24: □ | W24: はい
C25: ⑯ | E25: 加入団体について該当するものにチェックしてください
C26: □ | E26: 未加入 | O26: □ | Q26: ライフル射撃協会 | AA26: □ | AC26: クレー射撃協会
C27: ■ | E27: 地区猟友会 | O27: □ | Q27: 地区射撃協会 | AA27: ■ | AC27: その他（愛知連合猟友会）
C28: ⑰ | E28: ⑯ の加入団体において役職等があれば、 該当するものにチェックしてください
C29: ■ | E29: ない | O29: □ | Q29: 会長 | AA29: □ | AC29: 副会長
C30: □ | E30: その他 | H30: （ | AK30: ）
C31: ⑱ | E31: あなたの狩猟や射撃時の友人等について名前を教えてください
C32: 氏名 | F32: 宮田 清一 | V32: 居住地 | Z32: 田原市赤羽根町
C33: 氏名 | F33: 松岡 康之 | V33: 居住地 | Z33: 田原市田原町
C34: 氏名 | F34: 伊藤 あつし | V34: 居住地 | Z34: 田原市西神戸
C35: 氏名 | V35: 居住地
AH37: 以上

Sheet 実包関係（表）
B2: 別添2-3-1 | S2: (表) | AB2: 確 認
F3: 猟銃等検査受検票 （実包・遵守事項関係等） | AB3: 警察官
B4: 受験者 | C4: 氏 名 | H4: 鈴 木 翔 一 郎
F5: 空気銃のみを所持している方は 該当する箇所のみにチェックしてください
H6: 銃砲と実包（ライフル実包 散弾実包）を | AA6: ■ | AC6: はい | AG6: □ | AI6: いいえ
H7: 同一建物内で共に保管していますか
H8: 上記の質問において「はい」と回答された | Y8: 理由 | AA8: * 別棟がない為
H9: 方は その理由を簡記してください | AA9: * 間近に消費予定
H10: (間近に使用する予定が有る場合は。その用途及び時期) | AA10: * 射撃練習 9月下旬
H11: 銃砲の保管場所 | Q11: 例：自宅の2階押入内、○△銃砲店への委託保管
T12: 自宅 ２Ｆ 書斎押入れ
H13: 銃砲の保管庫は、一般的に発見しにくい場所に設置されてますか | AA13: ■ | AC13: はい | AG13: □ | AH13: いいえ
B15: 銃砲と実包 | H15: 銃砲の保管庫は、床や壁に固定されていますか | AA15: ■ | AC15: はい | AG15: □ | AH15: いいえ
B17: の保管場所 | H17: 銃砲を保管庫に収納するときは、確実に脱包を確認していますか | AA17: ■ | AC17: はい | AG17: □ | AH17: いいえ
B18: 保管方法等
H19: 銃砲を保管庫に収納するときは、分解や先台等の別保管をしていますか | AA19: ■ | AC19: はい | AG19: □ | AH19: いいえ
B20: について
H21: 銃砲を保管庫に収納するときは、チェーン錠による二重や三重ロックをしていますか | AA21: ■ | AC21: はい | AG21: □ | AH21: いいえ
H23: 実包の保管場所 | Q23: 例：自宅1階和室
R24: 自宅 １Ｆ 階段下押入れ
H25: 実包等の保管庫は、一般的に発見しにくい場所に設置されてますか | AA25: ■ | AC25: はい | AG25: □ | AH25: いいえ
H27: 銃砲や実包等の保管庫の鍵は自ら責任を持って管理していますか | AA27: ■ | AC27: はい | AG27: □ | AH27: いいえ
H29: 銃砲と実包等は別の保管庫で保管していますか | AA29: ■ | AC29: はい | AG29: □ | AH29: いいえ
B31: 帳 簿 | H31: ３年分の帳簿の保存がありますか | AA31: ■ | AC31: はい | AG31: □ | AH31: いいえ
H32: 消費等した年月日を記載していますか | AA32: ■ | AC32: はい | AG32: □ | AH32: いいえ
H33: 消費等した数量を記載していますか | AA33: ■ | AC33: はい | AG33: □ | AH33: いいえ
H34: 実包の種類（名称,番径）を記載してますか | AA34: ■ | AC34: はい | AG34: □ | AH34: いいえ
H35: 購入や消費した先の住所・所在地を記載してますか | AA35: ■ | AC35: はい | AG35: □ | AH35: いいえ
H36: 購入した場合の相手方の氏名,名称を記載していますか | AA36: ■ | AC36: はい | AG36: □ | AH36: いいえ
H37: 射撃場で実包を消費した場合には、スコアカード等資料を添付していますか | AA37: ■ | AC37: はい | AG37: □ | AH37: いいえ
R38: 別添2-3-2に続きます

Sheet 実包関係（裏
B2: 別添2-3-2 | T2: （裏）
H3: 猟場や射撃場に放置駐車した車両内に | W3: ■ | X3: していない | AC3: □ | AD3: 保管したことがある
H4: 銃砲や実包・空砲を保管していませんか
H5: 法律で規定されている数量以上の弾が | W5: ■ | X5: していない | AC5: □ | AD5: 改造したことがある
H6: 装てんできるように,改造していませんか
H7: 消音装置を所持していませんか | W7: ■ | X7: していない | AC7: □ | AD7: 所持している
B8: 遵守事項
H9: 法律上の許可を受けずに 実包・空砲を | W9: ■ | X9: していない | AC9: □ | AD9: 譲渡したことがある
B10: 関係 | H10: 知人に貸したり,譲渡したりしていませんか
H11: 銃砲を運搬,携帯するときは,許可証を | W11: ■ | X11: はい | AC11: □ | AD11: いいえ
H12: 一緒に携帯していますか
H13: 銃砲を携帯運搬するときは,容器に入れるか | W13: ■ | X13: はい | AC13: □ | AD13: いいえ
H14: おおいをかぶせる等の措置をしていますか
H15: 入手用途 | M15: 許可・無許可別 | U15: 保管数 | X15: 入手日 | AE15: 消費・交付予定日
H16: 狩 猟 | M16: ■ 公安委員会許可 | U16: 22 | W16: 個 | X16: R1 | Z16: 年 | AA16: 11 | AB16: 月 | AC16: 8 | AD16: 日 | AG16: 年 | AI16: 月 | AK16: 日
M17: （警察による許可） | Z17: 年 | AB17: 月 | AD17: 日 | AE17: R2年度に狩猟で 消費予定
M18: □ 無許可 | W18: 個 | Z18: 年 | AB18: 月 | AD18: 日 | AG18: 年 | AI18: 月 | AK18: 日
M19: （無許可譲受票）
H20: 標的射撃 | N20: (公安委員会許可) | U20: 114 | W20: 個 | X20: R2 | Z20: 年 | AA20: 11 | AB20: 月 | AC20: 8 | AD20: 日 | AE20: R2 | AG20: 年 | AH20: 9 | AI20: 月 | AJ20: 下旬ころ
H21: 有害駆除 | M21: □ 公安委員会許可 | U21: 0 | W21: 個 | X21: 未購入 | Z21: 年 | AB21: 月 | AD21: 日 | AG21: 年 | AI21: 月 | AK21: 日
M22: （警察による許可）
B23: 自 宅 で | M23: □ 無許可 | W23: 個 | Z23: 年 | AB23: 月 | AD23: 日 | AG23: 年 | AI23: 月 | AK23: 日
M24: （無許可譲受票）
B25: 保管している | H25: 火薬類 | M25: □ 公安委員会許可 | U25: □ 無煙火薬 グラム | AF25: □ | AG25: 銃用 | AK25: 個
M26: （警察による許可） | U26: □ 黒色火薬 グラム | AG26: 雷管
B27: 実 包 数 等 | M27: □ 無許可 | U27: □ 無煙火薬 グラム | AF27: □ | AG27: 銃用 | AK27: 個
M28: （無許可譲受票） | U28: □ 黒色火薬 グラム | AG28: 雷管
H29: 合計 | M29: 実包（空包） ５ 個 | V29: =U16+U20+U21 -> 136 | X29: 個 | Z29: 火薬類 | AI29: グラム
H30: 自宅保管中の実包等の措置 | U30: □ 残火薬として銃砲火薬店へ廃棄予定
U31: ■ 近日中に消費予定(予定日9月下旬日ころ)射撃装弾
U32: ■ その他（R2年度狩猟で消費予定）狩猟装弾
B33: 愛知県内では 自動車盗 住宅対象侵入盗が多発しており 全国的には 銃砲と適合実包が同時に
B34: 盗難被害となる事件が発生しています。
B35: 銃砲及実包等の保管管理を徹底してください。
